package exception;

/**
 * 异常处理机制中的try-catch
 */
public class TryCatchDemo {
    public static void main(String[] args) {
        System.out.println("程序开始了");
        try {//try语句块用来扩上可能出错的代码片段
      //      String a = null;
      //      String a = "";
              String a = "abc";
        /*
           如果str为null时,当虚拟机执行到下面的代码会发现这里存在
           空指针现象.于是虚拟机会实例化一个空指针异常的实例,并将其
           抛出.抛出后会检查报错的这句话是否被异常处理机制控制,如果
           没有则会将该异常抛出到当前方法外面,由调用该方法的代码去解决
           (这里相当于抛出的到main方法外面)
         */
            System.out.println(a.length());
            System.out.println(a.charAt(0));
            System.out.println("1111111");//try语句块中报错代码以下内容都不会执行!!!
            System.out.println(Integer.parseInt(a));
            //catch用来捕获try中出现的指针异常得以解决
        }catch(NullPointerException e){
           // System.out.println("空指针异常");
            //catch可以定义多个,当try中不同异常有不同处理方式时可以分别捕获
        }catch(StringIndexOutOfBoundsException e){
            System.out.println("字符串下标越界了");
        }catch (NumberFormatException e){
            System.out.println("字符串下标越界了");
            /*
                catch超类异常的意义:
                当try中某几类异常希望使用相同处理办法时,可以catch这些
                异常的超类
                在最后一个catch处捕获Exception也可以避免因为一个未处理
                的异常导致程序中断.

                当多个catch的异常之间存在继承关系时,子类型异常要在
                上面先行捕获,超类异常在下,否则编译不通过.
             */
        }catch(Exception e){
            System.out.println("出错");
        }
        System.out.println("程序结束了");

    }

}
